<?xml version="1.0" encoding="utf-8"?>
<!-- This URDF was automatically created by SolidWorks to URDF Exporter! Originally created by Stephen Brawner (brawner@gmail.com) 
     Commit Version: 1.6.0-4-g7f85cfe  Build Version: 1.6.7995.38578
     For more information, please see http://wiki.ros.org/sw_urdf_exporter -->
<robot
  name="m1u_description">
  <link
    name="base_link">
    <inertial>
      <origin
        xyz="-0.1114 0.17591 0.025474"
        rpy="0 0 0" />
      <mass
        value="7.8796" />
      <inertia
        ixx="0.079979"
        ixy="-2.0404E-09"
        ixz="5.7127E-08"
        iyy="0.051141"
        iyz="2.6407E-05"
        izz="0.13042" />
    </inertial>
    <visual>
      <origin
        xyz="0 0 0"
        rpy="0 0 0" />
      <geometry>
        <mesh
          filename="package://m1u_description/meshes/base_link.STL" />
      </geometry>
      <material
        name="">
        <color
          rgba="1 1 1 1" />
      </material>
    </visual>
    <collision>
      <origin
        xyz="0 0 0"
        rpy="0 0 0" />
      <geometry>
        <mesh
          filename="package://m1u_description/meshes/base_link_col.STL" />
      </geometry>
    </collision>
  </link>
  <link
    name="link1">
    <inertial>
      <origin
        xyz="0.0061177 0.00019417 0.087958"
        rpy="0 0 0" />
      <mass
        value="1.6773" />
      <inertia
        ixx="0.0057689"
        ixy="1.639E-07"
        ixz="5.2341E-06"
        iyy="0.0039153"
        iyz="2.0572E-09"
        izz="0.0028596" />
    </inertial>
    <visual>
      <origin
        xyz="0 0 0"
        rpy="0 0 0" />
      <geometry>
        <mesh
          filename="package://m1u_description/meshes/link1.STL" />
      </geometry>
      <material
        name="">
        <color
          rgba="0.86667 0.9098 1 1" />
      </material>
    </visual>
    <collision>
      <origin
        xyz="0 0 0"
        rpy="0 0 0" />
      <geometry>
        <mesh
          filename="package://m1u_description/meshes/link1_col.STL" />
      </geometry>
    </collision>
  </link>
  <joint
    name="j1"
    type="revolute">
    <origin
      xyz="-0.11135 0.15 0.062"
      rpy="0 0 0" />
    <parent
      link="base_link" />
    <child
      link="link1" />
    <axis
      xyz="0 0 1" />
    <limit
      lower="-3"
      upper="3"
      effort="50"
      velocity="1" />
  </joint>
  <link
    name="link2">
    <inertial>
      <origin
        xyz="0.057214 9.84E-05 0.16426"
        rpy="0 0 0" />
      <mass
        value="3.2856" />
      <inertia
        ixx="0.051188"
        ixy="1.6038E-07"
        ixz="-9.1502E-06"
        iyy="0.047303"
        iyz="5.751E-09"
        izz="0.004433" />
    </inertial>
    <visual>
      <origin
        xyz="0 0 0"
        rpy="0 0 0" />
      <geometry>
        <mesh
          filename="package://m1u_description/meshes/link2.STL" />
      </geometry>
      <material
        name="">
        <color
          rgba="0.86667 0.9098 1 1" />
      </material>
    </visual>
    <collision>
      <origin
        xyz="0 0 0"
        rpy="0 0 0" />
      <geometry>
        <mesh
          filename="package://m1u_description/meshes/link2_col.STL" />
      </geometry>
    </collision>
  </link>
  <joint
    name="j2"
    type="revolute">
    <origin
      xyz="-0.054 0 0.1445"
      rpy="0 0 0" />
    <parent
      link="link1" />
    <child
      link="link2" />
    <axis
      xyz="1 0 0" />
    <limit
      lower="-2"
      upper="2"
      effort="50"
      velocity="1" />
  </joint>
  <link
    name="link3">
    <inertial>
      <origin
        xyz="0.039376 -0.092498 0.0077437"
        rpy="0 0 0" />
      <mass
        value="1.9327" />
      <inertia
        ixx="0.0084639"
        ixy="-5.5424E-08"
        ixz="9.6769E-10"
        iyy="0.0027233"
        iyz="1.0935E-05"
        izz="0.0069108" />
    </inertial>
    <visual>
      <origin
        xyz="0 0 0"
        rpy="0 0 0" />
      <geometry>
        <mesh
          filename="package://m1u_description/meshes/link3.STL" />
      </geometry>
      <material
        name="">
        <color
          rgba="0.86667 0.9098 1 1" />
      </material>
    </visual>
    <collision>
      <origin
        xyz="0 0 0"
        rpy="0 0 0" />
      <geometry>
        <mesh
          filename="package://m1u_description/meshes/link3_col.STL" />
      </geometry>
    </collision>
  </link>
  <joint
    name="j3"
    type="revolute">
    <origin
      xyz="0.0145 0 0.34"
      rpy="0 0 0" />
    <parent
      link="link2" />
    <child
      link="link3" />
    <axis
      xyz="-1 0 0" />
    <limit
      lower="-2"
      upper="2"
      effort="50"
      velocity="2" />
  </joint>
  <link
    name="link4">
    <inertial>
      <origin
        xyz="-0.00012966 -0.062233 -0.0040436"
        rpy="0 0 0" />
      <mass
        value="1.1685" />
      <inertia
        ixx="0.0019881"
        ixy="9.6769E-10"
        ixz="-6.3547E-08"
        iyy="0.0014229"
        iyz="5.672E-06"
        izz="0.0023972" />
    </inertial>
    <visual>
      <origin
        xyz="0 0 0"
        rpy="0 0 0" />
      <geometry>
        <mesh
          filename="package://m1u_description/meshes/link4.STL" />
      </geometry>
      <material
        name="">
        <color
          rgba="0.86667 0.9098 1 1" />
      </material>
    </visual>
    <collision>
      <origin
        xyz="0 0 0"
        rpy="0 0 0" />
      <geometry>
        <mesh
          filename="package://m1u_description/meshes/link4_col.STL" />
      </geometry>
    </collision>
  </link>
  <joint
    name="j4"
    type="revolute">
    <origin
      xyz="0.0395 -0.197 0"
      rpy="0 0 0" />
    <parent
      link="link3" />
    <child
      link="link4" />
    <axis
      xyz="0 -1 0" />
    <limit
      lower="-3"
      upper="3"
      effort="50"
      velocity="3" />
  </joint>
  <link
    name="link5">
    <inertial>
      <origin
        xyz="-0.00027872 -0.01747 -0.060001"
        rpy="0 0 0" />
      <mass
        value="0.5436" />
      <inertia
        ixx="0.00028276"
        ixy="-6.3547E-08"
        ixz="-9.6769E-10"
        iyy="0.00029666"
        iyz="-5.5424E-08"
        izz="0.00041219" />
    </inertial>
    <visual>
      <origin
        xyz="0 0 0"
        rpy="0 0 0" />
      <geometry>
        <mesh
          filename="package://m1u_description/meshes/link5.STL" />
      </geometry>
      <material
        name="">
        <color
          rgba="0.86667 0.9098 1 1" />
      </material>
    </visual>
    <collision>
      <origin
        xyz="0 0 0"
        rpy="0 0 0" />
      <geometry>
        <mesh
          filename="package://m1u_description/meshes/link5_col.STL" />
      </geometry>
    </collision>
  </link>
  <joint
    name="j5"
    type="revolute">
    <origin
      xyz="0 -0.14976 0.06"
      rpy="0 0 0" />
    <parent
      link="link4" />
    <child
      link="link5" />
    <axis
      xyz="0 0 -1" />
    <limit
      lower="-2"
      upper="2"
      effort="50"
      velocity="3" />
  </joint>
  <link
    name="link6">
    <inertial>
      <origin
        xyz="-1.4988E-15 -0.011336 -6.6613E-16"
        rpy="0 0 0" />
      <mass
        value="0.059887" />
      <inertia
        ixx="1.69E-05"
        ixy="1.7186E-19"
        ixz="1.628E-20"
        iyy="3.0067E-05"
        iyz="6.324E-20"
        izz="1.69E-05" />
    </inertial>
    <visual>
      <origin
        xyz="0 0 0"
        rpy="0 0 0" />
      <geometry>
        <mesh
          filename="package://m1u_description/meshes/link6.STL" />
      </geometry>
      <material
        name="">
        <color
          rgba="0.79216 0.81961 0.93333 1" />
      </material>
    </visual>
    <collision>
      <origin
        xyz="0 0 0"
        rpy="0 0 0" />
      <geometry>
        <mesh
          filename="package://m1u_description/meshes/link6_col.STL" />
      </geometry>
    </collision>
  </link>
  <joint
    name="j6"
    type="revolute">
    <origin
      xyz="0 -0.05 -0.06"
      rpy="0 0 0" />
    <parent
      link="link5" />
    <child
      link="link6" />
    <axis
      xyz="0 -1 0" />
    <limit
      lower="-10"
      upper="10"
      effort="50"
      velocity="8" />
  </joint>
</robot>